Workbook

Sheet Dashboard
A1: Dashboard
B2: Overall | C2: W | D2: L | E2: T | F2: PTS | G2: GF | H2: GA | I2: GD | J2: PCT | K2: MP
A3: 1 | B3: BRAZUKAS | C3: =COUNTIFS(GamesId!K:K,A3,GamesId!M:M,"WIN")+COUNTIFS(GamesId!L:L,A3,GamesId!M:M,"DEFEAT",GamesId!F:F,"<"&TODAY()) -> 33 | D3: =COUNTIFS(GamesId!K:K,A3,GamesId!M:M,"DEFEAT")+COUNTIFS(GamesId!L:L,A3,GamesId!M:M,"WIN",GamesId!F:F,"<"&TODAY()) -> 44 | E3: =COUNTIFS(GamesId!K:K,A3,GamesId!M:M,"TIE",GamesId!F:F,"<"&TODAY()) -> 13 | F3: =3*C3+E3 -> 112 | G3: =SUMIFS(GamesId!C:C,GamesId!K:K,A3)+SUMIFS(GamesId!E:E,GamesId!L:L,A3) -> 357 | H3: =SUMIFS(GamesId!C:C,GamesId!L:L,A3)+SUMIFS(GamesId!E:E,GamesId!K:K,A3) -> 381 | I3: =G3-H3 -> -24 | J3: =F3/(K3*3) -> 0.41481481 | K3: =C3+D3+E3 -> 90
A4: 2 | B4: RECEBA | C4: =COUNTIFS(GamesId!K:K,A4,GamesId!M:M,"WIN")+COUNTIFS(GamesId!L:L,A4,GamesId!M:M,"DEFEAT",GamesId!F:F,"<"&TODAY()) -> 13 | D4: =COUNTIFS(GamesId!K:K,A4,GamesId!M:M,"DEFEAT")+COUNTIFS(GamesId!L:L,A4,GamesId!M:M,"WIN",GamesId!F:F,"<"&TODAY()) -> 1 | E4: =COUNTIFS(GamesId!K:K,A4,GamesId!M:M,"TIE",GamesId!F:F,"<"&TODAY()) -> 6 | F4: =3*C4+E4 -> 45 | G4: =SUMIFS(GamesId!C:C,GamesId!K:K,A4)+SUMIFS(GamesId!E:E,GamesId!L:L,A4) -> 122 | H4: =SUMIFS(GamesId!C:C,GamesId!L:L,A4)+SUMIFS(GamesId!E:E,GamesId!K:K,A4) -> 63 | I4: =G4-H4 -> 59 | J4: =F4/(K4*3) -> 0.75 | K4: =C4+D4+E4 -> 20
B10: Gols | C10: Team Name | G10: Assists | H10: Team Name
B11: PlayerName | C11: Brazukas | D11: RECEBA FC | E11: Grand Total | G11: PlayerName | H11: Brazukas | I11: RECEBA FC | J11: Grand Total
B12: Arthur Mendes | C12: 5 | D12: 6 | E12: 11 | G12: Guilherme Kuster | H12: 3 | I12: 3 | J12: 6
B13: Guilherme Kuster | C13: 5 | D13: 3 | E13: 8 | G13: Rafael Mattos | H13: 4 | J13: 4
B14: Rafael Franco | C14: 1 | D14: 6 | E14: 7 | G14: Cleiton Góes | H14: 1 | I14: 3 | J14: 4
B15: Marcelo Mazzafera | D15: 5 | E15: 5 | G15: Sergio Filho | I15: 3 | J15: 3
B16: Ranieri Filho | C16: 1 | D16: 3 | E16: 4 | G16: Rafael Franco | H16: 1 | I16: 2 | J16: 3
B17: Sergio Filho | C17: 3 | E17: 3 | G17: Arthur Mendes | I17: 3 | J17: 3
B18: Pablo Rodrigues | D18: 3 | E18: 3 | G18: Marcelo Mazzafera | I18: 2 | J18: 2
B19: Cleiton Góes | C19: 1 | D19: 2 | E19: 3 | G19: Emerson Bernardes | I19: 2 | J19: 2
B20: Tamir Guy | C20: 2 | E20: 2 | G20: Caio Scofield | H20: 2 | J20: 2
B21: Gustavo Bitencourt | C21: 2 | E21: 2 | G21: Tamir Guy | H21: 1 | J21: 1
B22: Flavio | D22: 2 | E22: 2 | G22: Ranieri Filho | H22: 1 | J22: 1
B23: Rafael Mattos | C23: 1 | E23: 1 | G23: Joao Pinto | I23: 1 | J23: 1
B24: Joao Pinto | D24: 1 | E24: 1 | G24: Joao Barros | H24: 1 | J24: 1
B25: Joao Barros | C25: 1 | E25: 1 | G25: Gustavo Bitencourt | H25: 1 | J25: 1
B26: Grand Total | C26: 22 | D26: 31 | E26: 53 | G26: Grand Total | H26: 15 | I26: 19 | J26: 34

Sheet EventID
A1: EventID | B1: EventType | C1: Event | D1: TeamID | E1: MatchID | F1: PlayerID | G1: PlayerName | H1: Qty | I1: Desc | J1: Team Name | K1: Date | L1: Temporada
A2: 1 | B2: MatchStat | C2: Gol | D2: 1 | E2: =GamesId!A89 -> 87 | F2: 10 | G2: {=if(ISNUMBER(F2),index(PlayerID!B:B,MATCH(F2,PlayerID!A:A,0)),"")} -> Arthur Mendes | H2: 1 | I2: Arthur driblou 3 dividiu com goleiro e botou bola pra dentro | J2: {=INDEX(TeamsID!B:B,MATCH(D2,TeamsID!A:A,0))} -> Brazukas | K2: {=INDEX(GamesId!F:F,MATCH(E2,GamesId!A:A,0))} -> 45041 | L2: {=INDEX(GamesId!J:J,MATCH(E2,GamesId!A:A,0))} -> Tues Men's D Spring 23
A3: =A2+1 -> 2 | B3: MatchStat | C3: Gol | D3: 1 | E3: =E2 -> 87 | F3: 10 | G3: {=if(ISNUMBER(F3),index(PlayerID!B:B,MATCH(F3,PlayerID!A:A,0)),"")} -> Arthur Mendes | H3: 1 | I3: Arthur pegou rebote em chute do Kuster | J3: {=INDEX(TeamsID!B:B,MATCH(D3,TeamsID!A:A,0))} -> Brazukas | K3: {=INDEX(GamesId!F:F,MATCH(E3,GamesId!A:A,0))} -> 45041 | L3: {=INDEX(GamesId!J:J,MATCH(E3,GamesId!A:A,0))} -> Tues Men's D Spring 23
A4: =A3+1 -> 3 | B4: MatchStat | C4: Assist | D4: 2 | E4: =GamesId!A112 -> 110 | F4: 8 | G4: {=if(ISNUMBER(F4),index(PlayerID!B:B,MATCH(F4,PlayerID!A:A,0)),"")} -> Cleiton Góes | H4: 1 | I4: Claiton Assist pro gol 4 do Arthur. | J4: {=INDEX(TeamsID!B:B,MATCH(D4,TeamsID!A:A,0))} -> RECEBA FC | K4: {=INDEX(GamesId!F:F,MATCH(E4,GamesId!A:A,0))} -> 45043 | L4: {=INDEX(GamesId!J:J,MATCH(E4,GamesId!A:A,0))} -> Thurs Men's D Spring 23
A5: =A4+1 -> 4 | B5: MatchStat | C5: Gol | D5: 2 | E5: 110 | F5: 10 | G5: {=if(ISNUMBER(F5),index(PlayerID!B:B,MATCH(F5,PlayerID!A:A,0)),"")} -> Arthur Mendes | H5: 4 | I5: Arthur marcou 4 gols nesse jogo | J5: {=INDEX(TeamsID!B:B,MATCH(D5,TeamsID!A:A,0))} -> RECEBA FC | K5: {=INDEX(GamesId!F:F,MATCH(E5,GamesId!A:A,0))} -> 45043 | L5: {=INDEX(GamesId!J:J,MATCH(E5,GamesId!A:A,0))} -> Thurs Men's D Spring 23
A6: =A5+1 -> 5 | B6: MatchStat | C6: Blue Card | D6: 2 | E6: 110 | F6: 2 | G6: {=if(ISNUMBER(F6),index(PlayerID!B:B,MATCH(F6,PlayerID!A:A,0)),"")} -> Guilherme Souza | I6: Agarrou jogador no contra ataque | J6: {=INDEX(TeamsID!B:B,MATCH(D6,TeamsID!A:A,0))} -> RECEBA FC | K6: {=INDEX(GamesId!F:F,MATCH(E6,GamesId!A:A,0))} -> 45043 | L6: {=INDEX(GamesId!J:J,MATCH(E6,GamesId!A:A,0))} -> Thurs Men's D Spring 23
A7: =A6+1 -> 6 | B7: MatchStat | C7: Blue Card | D7: 2 | E7: 110 | F7: 7 | G7: {=if(ISNUMBER(F7),index(PlayerID!B:B,MATCH(F7,PlayerID!A:A,0)),"")} -> Sergio Filho | H7: 1 | I7: atrapalhou saida do goleiro | J7: {=INDEX(TeamsID!B:B,MATCH(D7,TeamsID!A:A,0))} -> RECEBA FC | K7: {=INDEX(GamesId!F:F,MATCH(E7,GamesId!A:A,0))} -> 45043 | L7: {=INDEX(GamesId!J:J,MATCH(E7,GamesId!A:A,0))} -> Thurs Men's D Spring 23
A8: =A7+1 -> 7 | B8: MatchStat | C8: Assist | D8: 2 | E8: 110 | F8: 7 | G8: {=if(ISNUMBER(F8),index(PlayerID!B:B,MATCH(F8,PlayerID!A:A,0)),"")} -> Sergio Filho | H8: 3 | I8: 1 pro gol so arthur, 1 pro rato, 1 pro rani | J8: {=INDEX(TeamsID!B:B,MATCH(D8,TeamsID!A:A,0))} -> RECEBA FC | K8: {=INDEX(GamesId!F:F,MATCH(E8,GamesId!A:A,0))} -> 45043 | L8: {=INDEX(GamesId!J:J,MATCH(E8,GamesId!A:A,0))} -> Thurs Men's D Spring 23
A9: =A8+1 -> 8 | B9: MatchStat | C9: Gol | D9: 2 | E9: 110 | F9: 4 | G9: {=if(ISNUMBER(F9),index(PlayerID!B:B,MATCH(F9,PlayerID!A:A,0)),"")} -> Rafael Franco | H9: 1 | I9: Assist do Sergio | J9: {=INDEX(TeamsID!B:B,MATCH(D9,TeamsID!A:A,0))} -> RECEBA FC | K9: {=INDEX(GamesId!F:F,MATCH(E9,GamesId!A:A,0))} -> 45043 | L9: {=INDEX(GamesId!J:J,MATCH(E9,GamesId!A:A,0))} -> Thurs Men's D Spring 23
A10: =A9+1 -> 9 | B10: MatchStat | C10: Gol | D10: 2 | E10: 110 | F10: 6 | G10: {=if(ISNUMBER(F10),index(PlayerID!B:B,MATCH(F10,PlayerID!A:A,0)),"")} -> Ranieri Filho | H10: 1 | I10: Assist to sergio | J10: {=INDEX(TeamsID!B:B,MATCH(D10,TeamsID!A:A,0))} -> RECEBA FC | K10: {=INDEX(GamesId!F:F,MATCH(E10,GamesId!A:A,0))} -> 45043 | L10: {=INDEX(GamesId!J:J,MATCH(E10,GamesId!A:A,0))} -> Thurs Men's D Spring 23
A11: =A10+1 -> 10 | B11: MatchStat | C11: Obs | D11: 2 | E11: 110 | G11: {=if(ISNUMBER(F11),index(PlayerID!B:B,MATCH(F11,PlayerID!A:A,0)),"")} | I11: Juiza FDP | J11: {=INDEX(TeamsID!B:B,MATCH(D11,TeamsID!A:A,0))} -> RECEBA FC | K11: {=INDEX(GamesId!F:F,MATCH(E11,GamesId!A:A,0))} -> 45043 | L11: {=INDEX(GamesId!J:J,MATCH(E11,GamesId!A:A,0))} -> Thurs Men's D Spring 23
A12: =A11+1 -> 11 | B12: TeamStat | C12: StarPlayer | D12: 5 | E12: 87 | G12: {=if(ISNUMBER(F12),index(PlayerID!B:B,MATCH(F12,PlayerID!A:A,0)),"")} | I12: Rexona q fede pra porra | J12: {=INDEX(TeamsID!B:B,MATCH(D12,TeamsID!A:A,0))} -> Blackfoot Ballers | K12: {=INDEX(GamesId!F:F,MATCH(E12,GamesId!A:A,0))} -> 45041 | L12: {=INDEX(GamesId!J:J,MATCH(E12,GamesId!A:A,0))} -> Tues Men's D Spring 23
A13: =A12+1 -> 12 | B13: MatchStat | C13: MissedPK | D13: 1 | E13: =GamesId!A88 -> 86 | F13: 9 | G13: {=if(ISNUMBER(F13),index(PlayerID!B:B,MATCH(F13,PlayerID!A:A,0)),"")} -> Guilherme Kuster | H13: 1 | I13: Kuster Perdeu penalti | J13: {=INDEX(TeamsID!B:B,MATCH(D13,TeamsID!A:A,0))} -> Brazukas | K13: {=INDEX(GamesId!F:F,MATCH(E13,GamesId!A:A,0))} -> 45034 | L13: {=INDEX(GamesId!J:J,MATCH(E13,GamesId!A:A,0))} -> Tues Men's D Spring 23
A14: =A13+1 -> 13 | B14: MatchStat | C14: Gol | D14: 1 | E14: 88 | F14: 10 | G14: {=if(ISNUMBER(F14),index(PlayerID!B:B,MATCH(F14,PlayerID!A:A,0)),"")} -> Arthur Mendes | H14: 1 | I14: Gol 1- Arthur Chuta forte da ponta direita. | J14: {=INDEX(TeamsID!B:B,MATCH(D14,TeamsID!A:A,0))} -> Brazukas | K14: {=INDEX(GamesId!F:F,MATCH(E14,GamesId!A:A,0))} -> 45048 | L14: {=INDEX(GamesId!J:J,MATCH(E14,GamesId!A:A,0))} -> Tues Men's D Spring 23
A15: =A14+1 -> 14 | B15: MatchStat | C15: Gol | D15: 1 | E15: 88 | F15: 9 | G15: {=if(ISNUMBER(F15),index(PlayerID!B:B,MATCH(F15,PlayerID!A:A,0)),"")} -> Guilherme Kuster | H15: 1 | I15: Gol 2 - Kuster Chuta de canhota do meio da rua cruzado. Bola vai no canto e goleiro aceita | J15: {=INDEX(TeamsID!B:B,MATCH(D15,TeamsID!A:A,0))} -> Brazukas | K15: {=INDEX(GamesId!F:F,MATCH(E15,GamesId!A:A,0))} -> 45048 | L15: {=INDEX(GamesId!J:J,MATCH(E15,GamesId!A:A,0))} -> Tues Men's D Spring 23
A16: =A15+1 -> 15 | B16: MatchStat | C16: Gol | D16: 1 | E16: 88 | F16: 8 | G16: {=if(ISNUMBER(F16),index(PlayerID!B:B,MATCH(F16,PlayerID!A:A,0)),"")} -> Cleiton Góes | H16: 1 | I16: Gol 3 - Cleiton dribla 2 na entrada da area e bate por cima do goleiro. Golaço | J16: {=INDEX(TeamsID!B:B,MATCH(D16,TeamsID!A:A,0))} -> Brazukas | K16: {=INDEX(GamesId!F:F,MATCH(E16,GamesId!A:A,0))} -> 45048 | L16: {=INDEX(GamesId!J:J,MATCH(E16,GamesId!A:A,0))} -> Tues Men's D Spring 23
A17: =A16+1 -> 16 | B17: MatchStat | C17: Gol | D17: 1 | E17: 88 | F17: 9 | G17: {=if(ISNUMBER(F17),index(PlayerID!B:B,MATCH(F17,PlayerID!A:A,0)),"")} -> Guilherme Kuster | H17: 1 | I17: Gol 4 - Kuster pegar rebote na area | J17: {=INDEX(TeamsID!B:B,MATCH(D17,TeamsID!A:A,0))} -> Brazukas | K17: {=INDEX(GamesId!F:F,MATCH(E17,GamesId!A:A,0))} -> 45048 | L17: {=INDEX(GamesId!J:J,MATCH(E17,GamesId!A:A,0))} -> Tues Men's D Spring 23
A18: =A17+1 -> 17 | B18: MatchStat | C18: Gol | D18: 1 | E18: 88 | F18: 7 | G18: {=if(ISNUMBER(F18),index(PlayerID!B:B,MATCH(F18,PlayerID!A:A,0)),"")} -> Sergio Filho | H18: 1 | I18: Gol 5 - Sergio faz gol em bela triangulacao. Assist do Rani | J18: {=INDEX(TeamsID!B:B,MATCH(D18,TeamsID!A:A,0))} -> Brazukas | K18: {=INDEX(GamesId!F:F,MATCH(E18,GamesId!A:A,0))} -> 45048 | L18: {=INDEX(GamesId!J:J,MATCH(E18,GamesId!A:A,0))} -> Tues Men's D Spring 23
A19: =A18+1 -> 18 | B19: MatchStat | C19: Gol | D19: 1 | E19: 88 | F19: 7 | G19: {=if(ISNUMBER(F19),index(PlayerID!B:B,MATCH(F19,PlayerID!A:A,0)),"")} -> Sergio Filho | H19: 1 | I19: Gol 6 - Em outra triangulacao , Rafa matos desvia e bola sobra no meio da area para Sergio botar pra dentro | J19: {=INDEX(TeamsID!B:B,MATCH(D19,TeamsID!A:A,0))} -> Brazukas | K19: {=INDEX(GamesId!F:F,MATCH(E19,GamesId!A:A,0))} -> 45048 | L19: {=INDEX(GamesId!J:J,MATCH(E19,GamesId!A:A,0))} -> Tues Men's D Spring 23
A20: =A19+1 -> 19 | B20: MatchStat | C20: Assist | D20: 1 | E20: 88 | F20: 18 | G20: {=if(ISNUMBER(F20),index(PlayerID!B:B,MATCH(F20,PlayerID!A:A,0)),"")} -> Rafael Mattos | H20: 1 | I20: Gol 1- Arthur Chuta forte da ponta direita. | J20: {=INDEX(TeamsID!B:B,MATCH(D20,TeamsID!A:A,0))} -> Brazukas | K20: {=INDEX(GamesId!F:F,MATCH(E20,GamesId!A:A,0))} -> 45048 | L20: {=INDEX(GamesId!J:J,MATCH(E20,GamesId!A:A,0))} -> Tues Men's D Spring 23
A21: =A20+1 -> 20 | B21: MatchStat | C21: Assist | D21: 1 | E21: 88 | F21: 6 | G21: {=if(ISNUMBER(F21),index(PlayerID!B:B,MATCH(F21,PlayerID!A:A,0)),"")} -> Ranieri Filho | H21: 1 | I21: Gol 5 - Sergio faz gol em bela triangulacao. Assist do Rani | J21: {=INDEX(TeamsID!B:B,MATCH(D21,TeamsID!A:A,0))} -> Brazukas | K21: {=INDEX(GamesId!F:F,MATCH(E21,GamesId!A:A,0))} -> 45048 | L21: {=INDEX(GamesId!J:J,MATCH(E21,GamesId!A:A,0))} -> Tues Men's D Spring 23
A22: =A21+1 -> 21 | B22: MatchStat | C22: Assist | D22: 1 | E22: 88 | F22: 18 | G22: {=if(ISNUMBER(F22),index(PlayerID!B:B,MATCH(F22,PlayerID!A:A,0)),"")} -> Rafael Mattos | H22: 1 | I22: Gol 6 - Em outra triangulacao , Rafa matos desvia e bola sobra no meio da area para Sergio botar pra dentro | J22: {=INDEX(TeamsID!B:B,MATCH(D22,TeamsID!A:A,0))} -> Brazukas | K22: {=INDEX(GamesId!F:F,MATCH(E22,GamesId!A:A,0))} -> 45048 | L22: {=INDEX(GamesId!J:J,MATCH(E22,GamesId!A:A,0))} -> Tues Men's D Spring 23
A23: =A22+1 -> 22 | B23: MatchStat | C23: Assist | D23: 1 | E23: 88 | F23: 13 | G23: {=if(ISNUMBER(F23),index(PlayerID!B:B,MATCH(F23,PlayerID!A:A,0)),"")} -> Caio Scofield | H23: 1 | I23: Gol 4 - Kuster pegar rebote na area | J23: {=INDEX(TeamsID!B:B,MATCH(D23,TeamsID!A:A,0))} -> Brazukas | K23: {=INDEX(GamesId!F:F,MATCH(E23,GamesId!A:A,0))} -> 45048 | L23: {=INDEX(GamesId!J:J,MATCH(E23,GamesId!A:A,0))} -> Tues Men's D Spring 23
A24: =A23+1 -> 23 | B24: TeamStat | C24: StarPlayer | D24: 5 | E24: 88 | G24: {=if(ISNUMBER(F24),index(PlayerID!B:B,MATCH(F24,PlayerID!A:A,0)),"")} | I24: Goleiro Higuita | J24: {=INDEX(TeamsID!B:B,MATCH(D24,TeamsID!A:A,0))} -> Blackfoot Ballers | K24: {=INDEX(GamesId!F:F,MATCH(E24,GamesId!A:A,0))} -> 45048 | L24: {=INDEX(GamesId!J:J,MATCH(E24,GamesId!A:A,0))} -> Tues Men's D Spring 23
A25: =A24+1 -> 24 | B25: MatchStat | C25: Obs | D25: 1 | E25: 88 | G25: {=if(ISNUMBER(F25),index(PlayerID!B:B,MATCH(F25,PlayerID!A:A,0)),"")} | I25: Sérgio perdendo bola e mandando aí canela pra não voltar , cara mandou um alley woop pro gol | J25: {=INDEX(TeamsID!B:B,MATCH(D25,TeamsID!A:A,0))} -> Brazukas | K25: {=INDEX(GamesId!F:F,MATCH(E25,GamesId!A:A,0))} -> 45048 | L25: {=INDEX(GamesId!J:J,MATCH(E25,GamesId!A:A,0))} -> Tues Men's D Spring 23
A26: =A25+1 -> 25 | B26: MatchStat | C26: Gol | D26: 2 | E26: 111 | F26: 9 | G26: {=if(ISNUMBER(F26),index(PlayerID!B:B,MATCH(F26,PlayerID!A:A,0)),"")} -> Guilherme Kuster | H26: 1 | I26: Gol 1- Gol kuster. Assistencia usando tabela do Arthur | J26: {=INDEX(TeamsID!B:B,MATCH(D26,TeamsID!A:A,0))} -> RECEBA FC | K26: {=INDEX(GamesId!F:F,MATCH(E26,GamesId!A:A,0))} -> 45050 | L26: {=INDEX(GamesId!J:J,MATCH(E26,GamesId!A:A,0))} -> Thurs Men's D Spring 23
A27: =A26+1 -> 26 | B27: MatchStat | C27: Gol | D27: 2 | E27: 111 | F27: 14 | G27: {=if(ISNUMBER(F27),index(PlayerID!B:B,MATCH(F27,PlayerID!A:A,0)),"")} -> Marcelo Mazzafera | H27: 1 | I27: Gol 2- Golasso do mazza. Golasso pq dificultou o lance sozinho aí teve q driblar uns 3 | J27: {=INDEX(TeamsID!B:B,MATCH(D27,TeamsID!A:A,0))} -> RECEBA FC | K27: {=INDEX(GamesId!F:F,MATCH(E27,GamesId!A:A,0))} -> 45050 | L27: {=INDEX(GamesId!J:J,MATCH(E27,GamesId!A:A,0))} -> Thurs Men's D Spring 23
A28: =A27+1 -> 27 | B28: MatchStat | C28: Gol | D28: 2 | E28: 111 | F28: 4 | G28: {=if(ISNUMBER(F28),index(PlayerID!B:B,MATCH(F28,PlayerID!A:A,0)),"")} -> Rafael Franco | H28: 1 | I28: Gol 3- Rato chute da ponta esquerda. Assist Cleiton | J28: {=INDEX(TeamsID!B:B,MATCH(D28,TeamsID!A:A,0))} -> RECEBA FC | K28: {=INDEX(GamesId!F:F,MATCH(E28,GamesId!A:A,0))} -> 45050 | L28: {=INDEX(GamesId!J:J,MATCH(E28,GamesId!A:A,0))} -> Thurs Men's D Spring 23
A29: =A28+1 -> 28 | B29: MatchStat | C29: Gol | D29: 2 | E29: 111 | F29: 9 | G29: {=if(ISNUMBER(F29),index(PlayerID!B:B,MATCH(F29,PlayerID!A:A,0)),"")} -> Guilherme Kuster | H29: 1 | I29: Gol 4-Kuster chute de longe. Goleirão q tava bem foi dar golpe de vista e passou vergonha. Não lembro da assists. Acho q kuster roubou bola | J29: {=INDEX(TeamsID!B:B,MATCH(D29,TeamsID!A:A,0))} -> RECEBA FC | K29: {=INDEX(GamesId!F:F,MATCH(E29,GamesId!A:A,0))} -> 45050 | L29: {=INDEX(GamesId!J:J,MATCH(E29,GamesId!A:A,0))} -> Thurs Men's D Spring 23
A30: =A29+1 -> 29 | B30: MatchStat | C30: Gol | D30: 2 | E30: 111 | F30: 4 | G30: {=if(ISNUMBER(F30),index(PlayerID!B:B,MATCH(F30,PlayerID!A:A,0)),"")} -> Rafael Franco | H30: 1 | I30: Gol 5- Rato rouba bola no ataque num bate rebate e poe pra dentro | J30: {=INDEX(TeamsID!B:B,MATCH(D30,TeamsID!A:A,0))} -> RECEBA FC | K30: {=INDEX(GamesId!F:F,MATCH(E30,GamesId!A:A,0))} -> 45050 | L30: {=INDEX(GamesId!J:J,MATCH(E30,GamesId!A:A,0))} -> Thurs Men's D Spring 23
A31: =A30+1 -> 30 | B31: MatchStat | C31: Gol | D31: 2 | E31: 111 | F31: 10 | G31: {=if(ISNUMBER(F31),index(PlayerID!B:B,MATCH(F31,PlayerID!A:A,0)),"")} -> Arthur Mendes | H31: 1 | I31: Gol 6- Arthur recebe Passe de penis domina na velocidade pra cima do zagueiro e bate no meio das perna do goleiro | J31: {=INDEX(TeamsID!B:B,MATCH(D31,TeamsID!A:A,0))} -> RECEBA FC | K31: {=INDEX(GamesId!F:F,MATCH(E31,GamesId!A:A,0))} -> 45050 | L31: {=INDEX(GamesId!J:J,MATCH(E31,GamesId!A:A,0))} -> Thurs Men's D Spring 23
A32: =A31+1 -> 31 | B32: MatchStat | C32: Assist | D32: 2 | E32: 111 | F32: 10 | G32: {=if(ISNUMBER(F32),index(PlayerID!B:B,MATCH(F32,PlayerID!A:A,0)),"")} -> Arthur Mendes | H32: 1 | I32: Gol 1- Gol kuster. Assistencia usando tabela do Arthur | J32: {=INDEX(TeamsID!B:B,MATCH(D32,TeamsID!A:A,0))} -> RECEBA FC | K32: {=INDEX(GamesId!F:F,MATCH(E32,GamesId!A:A,0))} -> 45050 | L32: {=INDEX(GamesId!J:J,MATCH(E32,GamesId!A:A,0))} -> Thurs Men's D Spring 23
A33: =A32+1 -> 32 | B33: MatchStat | C33: Assist | D33: 2 | E33: 111 | F33: 8 | G33: {=if(ISNUMBER(F33),index(PlayerID!B:B,MATCH(F33,PlayerID!A:A,0)),"")} -> Cleiton Góes | H33: 1 | I33: Gol 3- Rato chute da ponta esquerda. Assist Cleiton | J33: {=INDEX(TeamsID!B:B,MATCH(D33,TeamsID!A:A,0))} -> RECEBA FC | K33: {=INDEX(GamesId!F:F,MATCH(E33,GamesId!A:A,0))} -> 45050 | L33: {=INDEX(GamesId!J:J,MATCH(E33,GamesId!A:A,0))} -> Thurs Men's D Spring 23
A34: =A33+1 -> 33 | B34: MatchStat | C34: Assist | D34: 2 | E34: 111 | F34: 3 | G34: {=if(ISNUMBER(F34),index(PlayerID!B:B,MATCH(F34,PlayerID!A:A,0)),"")} -> Joao Pinto | H34: 1 | I34: =I31 -> Gol 6- Arthur recebe Passe de penis domina na velocidade pra cima do zagueiro e bate no meio das perna do goleiro | J34: {=INDEX(TeamsID!B:B,MATCH(D34,TeamsID!A:A,0))} -> RECEBA FC | K34: {=INDEX(GamesId!F:F,MATCH(E34,GamesId!A:A,0))} -> 45050 | L34: {=INDEX(GamesId!J:J,MATCH(E34,GamesId!A:A,0))} -> Thurs Men's D Spring 23
A35: =A34+1 -> 34 | B35: MatchStat | C35: Missed Chance | D35: 1 | E35: 111 | F35: 14 | G35: {=if(ISNUMBER(F35),index(PlayerID!B:B,MATCH(F35,PlayerID!A:A,0)),"")} -> Marcelo Mazzafera | H35: 2 | I35: Mazza perdeu um gol 100% na escala deivid. Outro 50% no final do jogo | J35: {=INDEX(TeamsID!B:B,MATCH(D35,TeamsID!A:A,0))} -> Brazukas | K35: {=INDEX(GamesId!F:F,MATCH(E35,GamesId!A:A,0))} -> 45050 | L35: {=INDEX(GamesId!J:J,MATCH(E35,GamesId!A:A,0))} -> Thurs Men's D Spring 23
A36: =A35+1 -> 35 | B36: MatchStat | C36: Gol | D36: 1 | E36: 89 | F36: 5 | G36: {=if(ISNUMBER(F36),index(PlayerID!B:B,MATCH(F36,PlayerID!A:A,0)),"")} -> Joao Barros | H36: 1 | I36: Gol 1- Joao Barros rouba bola no campo de defesa conduz a bola ate a intermediaria e solta um tiro de longa distancia | J36: {=INDEX(TeamsID!B:B,MATCH(D36,TeamsID!A:A,0))} -> Brazukas | K36: {=INDEX(GamesId!F:F,MATCH(E36,GamesId!A:A,0))} -> 45055 | L36: {=INDEX(GamesId!J:J,MATCH(E36,GamesId!A:A,0))} -> Tues Men's D Spring 23
A37: =A36+1 -> 36 | B37: MatchStat | C37: Gol | D37: 1 | E37: 89 | F37: 15 | G37: {=if(ISNUMBER(F37),index(PlayerID!B:B,MATCH(F37,PlayerID!A:A,0)),"")} -> Gustavo Bitencourt | H37: 1 | I37: Gol 2 - Gol Gustavo. Assist Cleiton | J37: {=INDEX(TeamsID!B:B,MATCH(D37,TeamsID!A:A,0))} -> Brazukas | K37: {=INDEX(GamesId!F:F,MATCH(E37,GamesId!A:A,0))} -> 45055 | L37: {=INDEX(GamesId!J:J,MATCH(E37,GamesId!A:A,0))} -> Tues Men's D Spring 23
A38: =A37+1 -> 37 | B38: MatchStat | C38: Gol | D38: 1 | E38: 89 | F38: 16 | G38: {=if(ISNUMBER(F38),index(PlayerID!B:B,MATCH(F38,PlayerID!A:A,0)),"")} -> Tamir Guy | H38: 1 | I38: Gol 3 - Gol do tamir depois de passe do Caio | J38: {=INDEX(TeamsID!B:B,MATCH(D38,TeamsID!A:A,0))} -> Brazukas | K38: {=INDEX(GamesId!F:F,MATCH(E38,GamesId!A:A,0))} -> 45055 | L38: {=INDEX(GamesId!J:J,MATCH(E38,GamesId!A:A,0))} -> Tues Men's D Spring 23
A39: =A38+1 -> 38 | B39: MatchStat | C39: Gol | D39: 1 | E39: 89 | F39: 10 | G39: {=if(ISNUMBER(F39),index(PlayerID!B:B,MATCH(F39,PlayerID!A:A,0)),"")} -> Arthur Mendes | H39: 1 | I39: Gol 4 - Gol Arthur, chute cruzado da ponta direita. Assit do tamir cobrando lateral. | J39: {=INDEX(TeamsID!B:B,MATCH(D39,TeamsID!A:A,0))} -> Brazukas | K39: {=INDEX(GamesId!F:F,MATCH(E39,GamesId!A:A,0))} -> 45055 | L39: {=INDEX(GamesId!J:J,MATCH(E39,GamesId!A:A,0))} -> Tues Men's D Spring 23
A40: =A39+1 -> 39 | B40: MatchStat | C40: Assist | D40: 1 | E40: 89 | F40: 8 | G40: {=if(ISNUMBER(F40),index(PlayerID!B:B,MATCH(F40,PlayerID!A:A,0)),"")} -> Cleiton Góes | H40: 1 | I40: Gol 2 - Gol Gustavo. Assist Cleiton | J40: {=INDEX(TeamsID!B:B,MATCH(D40,TeamsID!A:A,0))} -> Brazukas | K40: {=INDEX(GamesId!F:F,MATCH(E40,GamesId!A:A,0))} -> 45055 | L40: {=INDEX(GamesId!J:J,MATCH(E40,GamesId!A:A,0))} -> Tues Men's D Spring 23
...

Sheet GamesId
A1: GameID | B1: Home_Team | C1: Home_Score | D1: Away_Team | E1: Away_Score | F1: Date | G1: Time | H1: Org | I1: Venue | J1: League | K1: HomeID | L1: AwayID | M1: Home Result
A2: 1 | B2: {=INDEX(TeamsID!B:B,MATCH(K2,TeamsID!A:A,0))} -> Brazukas | C2: 4 | D2: {=INDEX(TeamsID!B:B,MATCH(L2,TeamsID!A:A,0))} -> BB 2.0 | E2: 2 | F2: 44383 | G2: 0.42361111 | H2: Magnuson | J2: Tues Men's D Summer 21 | K2: 1 | L2: 34 | M2: =IF(C2>E2,"WIN",if(C2<E2,"DEFEAT","TIE")) -> WIN
A3: =A2+1 -> 2 | B3: {=INDEX(TeamsID!B:B,MATCH(K3,TeamsID!A:A,0))} -> Immune to Defense | C3: 4 | D3: {=INDEX(TeamsID!B:B,MATCH(L3,TeamsID!A:A,0))} -> Brazukas | E3: 1 | F3: =F2+7 -> 44390 | G3: 0.38888889 | H3: Magnuson | J3: Tues Men's D Summer 21 | K3: 3 | L3: 1 | M3: =IF(C3>E3,"WIN",if(C3<E3,"DEFEAT","TIE")) -> WIN
A4: =A3+1 -> 3 | B4: {=INDEX(TeamsID!B:B,MATCH(K4,TeamsID!A:A,0))} -> Brazukas | C4: 1 | D4: {=INDEX(TeamsID!B:B,MATCH(L4,TeamsID!A:A,0))} -> Seattle Sperm Bank | E4: 2 | F4: 44398 | G4: 0.32986111 | H4: Magnuson | J4: Tues Men's D Summer 21 | K4: 1 | L4: 35 | M4: =IF(C4>E4,"WIN",if(C4<E4,"DEFEAT","TIE")) -> DEFEAT
A5: =A4+1 -> 4 | B5: {=INDEX(TeamsID!B:B,MATCH(K5,TeamsID!A:A,0))} -> Husar | C5: 3 | D5: {=INDEX(TeamsID!B:B,MATCH(L5,TeamsID!A:A,0))} -> Brazukas | E5: 4 | F5: 44404 | G5: 0.31597222 | H5: Magnuson | J5: Tues Men's D Summer 21 | K5: 4 | L5: 1 | M5: =IF(C5>E5,"WIN",if(C5<E5,"DEFEAT","TIE")) -> DEFEAT
A6: =A5+1 -> 5 | B6: {=INDEX(TeamsID!B:B,MATCH(K6,TeamsID!A:A,0))} -> Brazukas | C6: 8 | D6: {=INDEX(TeamsID!B:B,MATCH(L6,TeamsID!A:A,0))} -> LivePerson | E6: 4 | F6: =F5+7 -> 44411 | G6: 0.3125 | H6: Magnuson | J6: Tues Men's D Summer 21 | K6: 1 | L6: 36 | M6: =IF(C6>E6,"WIN",if(C6<E6,"DEFEAT","TIE")) -> WIN
A7: =A6+1 -> 6 | B7: {=INDEX(TeamsID!B:B,MATCH(K7,TeamsID!A:A,0))} -> Brazukas | C7: 4 | D7: {=INDEX(TeamsID!B:B,MATCH(L7,TeamsID!A:A,0))} -> Un Real | E7: 4 | F7: 44419 | G7: 0.25694444 | H7: Magnuson | J7: Tues Men's D Summer 21 | K7: 1 | L7: 17 | M7: =IF(C7>E7,"WIN",if(C7<E7,"DEFEAT","TIE")) -> TIE
A8: =A7+1 -> 7 | B8: {=INDEX(TeamsID!B:B,MATCH(K8,TeamsID!A:A,0))} -> Brazukas | C8: 7 | D8: {=INDEX(TeamsID!B:B,MATCH(L8,TeamsID!A:A,0))} -> Blue Horseshoes | E8: 4 | F8: 44425 | H8: Magnuson | J8: Tues Men's D Fall 21 | K8: 1 | L8: 37 | M8: =IF(C8>E8,"WIN",if(C8<E8,"DEFEAT","TIE")) -> WIN
A9: =A8+1 -> 8 | B9: {=INDEX(TeamsID!B:B,MATCH(K9,TeamsID!A:A,0))} -> Brazukas | C9: 3 | D9: {=INDEX(TeamsID!B:B,MATCH(L9,TeamsID!A:A,0))} -> Magma | E9: 3 | F9: 44432 | H9: Magnuson | J9: Tues Men's D Fall 21 | K9: 1 | L9: 12 | M9: =IF(C9>E9,"WIN",if(C9<E9,"DEFEAT","TIE")) -> TIE
A10: =A9+1 -> 9 | B10: {=INDEX(TeamsID!B:B,MATCH(K10,TeamsID!A:A,0))} -> Husar | C10: 7 | D10: {=INDEX(TeamsID!B:B,MATCH(L10,TeamsID!A:A,0))} -> Brazukas | E10: 1 | F10: 44439 | H10: Magnuson | J10: Tues Men's D Fall 21 | K10: 4 | L10: 1 | M10: =IF(C10>E10,"WIN",if(C10<E10,"DEFEAT","TIE")) -> WIN
A11: =A10+1 -> 10 | B11: {=INDEX(TeamsID!B:B,MATCH(K11,TeamsID!A:A,0))} -> Blackfoot Ballers | C11: 7 | D11: {=INDEX(TeamsID!B:B,MATCH(L11,TeamsID!A:A,0))} -> Brazukas | E11: 3 | F11: 44446 | H11: Magnuson | J11: Tues Men's D Fall 21 | K11: 5 | L11: 1 | M11: =IF(C11>E11,"WIN",if(C11<E11,"DEFEAT","TIE")) -> WIN
A12: =A11+1 -> 11 | B12: {=INDEX(TeamsID!B:B,MATCH(K12,TeamsID!A:A,0))} -> Brazukas | C12: 4 | D12: {=INDEX(TeamsID!B:B,MATCH(L12,TeamsID!A:A,0))} -> FC Twente One | E12: 3 | F12: 44453 | H12: Magnuson | J12: Tues Men's D Fall 21 | K12: 1 | L12: 10 | M12: =IF(C12>E12,"WIN",if(C12<E12,"DEFEAT","TIE")) -> WIN
A13: =A12+1 -> 12 | B13: {=INDEX(TeamsID!B:B,MATCH(K13,TeamsID!A:A,0))} -> KOMPAS | C13: 3 | D13: {=INDEX(TeamsID!B:B,MATCH(L13,TeamsID!A:A,0))} -> Brazukas | E13: 4 | F13: 44460 | H13: Magnuson | J13: Tues Men's D Fall 21 | K13: 6 | L13: 1 | M13: =IF(C13>E13,"WIN",if(C13<E13,"DEFEAT","TIE")) -> DEFEAT
A14: =A13+1 -> 13 | B14: {=INDEX(TeamsID!B:B,MATCH(K14,TeamsID!A:A,0))} -> Brazukas | C14: 3 | D14: {=INDEX(TeamsID!B:B,MATCH(L14,TeamsID!A:A,0))} -> My Chemical Bromance | E14: 3 | F14: 44467 | H14: Magnuson | J14: Tues Men's D Fall 21 | K14: 1 | L14: 38 | M14: =IF(C14>E14,"WIN",if(C14<E14,"DEFEAT","TIE")) -> TIE
A15: =A14+1 -> 14 | B15: {=INDEX(TeamsID!B:B,MATCH(K15,TeamsID!A:A,0))} -> Brazukas | C15: 4 | D15: {=INDEX(TeamsID!B:B,MATCH(L15,TeamsID!A:A,0))} -> Seattle Americans | E15: 6 | F15: 44474 | H15: Magnuson | J15: Tues Men's D Fall 21 | K15: 1 | L15: 9 | M15: =IF(C15>E15,"WIN",if(C15<E15,"DEFEAT","TIE")) -> DEFEAT
A16: =A15+1 -> 15 | B16: {=INDEX(TeamsID!B:B,MATCH(K16,TeamsID!A:A,0))} -> Advil United | C16: 6 | D16: {=INDEX(TeamsID!B:B,MATCH(L16,TeamsID!A:A,0))} -> Brazukas | E16: 7 | F16: 44481 | H16: Magnuson | J16: Tues Men's D Winter 21 | K16: 7 | L16: 1 | M16: =IF(C16>E16,"WIN",if(C16<E16,"DEFEAT","TIE")) -> DEFEAT
A17: =A16+1 -> 16 | B17: {=INDEX(TeamsID!B:B,MATCH(K17,TeamsID!A:A,0))} -> Brazukas | C17: 6 | D17: {=INDEX(TeamsID!B:B,MATCH(L17,TeamsID!A:A,0))} -> No Tactics, Just Vibes | E17: 4 | F17: =F16+7 -> 44488 | H17: Magnuson | J17: Tues Men's D Winter 21 | K17: 1 | L17: 11 | M17: =IF(C17>E17,"WIN",if(C17<E17,"DEFEAT","TIE")) -> WIN
A18: =A17+1 -> 17 | B18: {=INDEX(TeamsID!B:B,MATCH(K18,TeamsID!A:A,0))} -> Brazukas | C18: 2 | D18: {=INDEX(TeamsID!B:B,MATCH(L18,TeamsID!A:A,0))} -> Crouch Potatoes | E18: 6 | F18: =F17+7 -> 44495 | H18: Magnuson | J18: Tues Men's D Winter 21 | K18: 1 | L18: 14 | M18: =IF(C18>E18,"WIN",if(C18<E18,"DEFEAT","TIE")) -> DEFEAT
A19: =A18+1 -> 18 | B19: {=INDEX(TeamsID!B:B,MATCH(K19,TeamsID!A:A,0))} -> Brazukas | C19: 4 | D19: {=INDEX(TeamsID!B:B,MATCH(L19,TeamsID!A:A,0))} -> Blackfoot Ballers | E19: 8 | F19: =F18+7 -> 44502 | H19: Magnuson | J19: Tues Men's D Winter 21 | K19: 1 | L19: 5 | M19: =IF(C19>E19,"WIN",if(C19<E19,"DEFEAT","TIE")) -> DEFEAT
A20: =A19+1 -> 19 | B20: {=INDEX(TeamsID!B:B,MATCH(K20,TeamsID!A:A,0))} -> Brazukas | C20: 3 | D20: {=INDEX(TeamsID!B:B,MATCH(L20,TeamsID!A:A,0))} -> Crouch Potatoes | E20: 0 | F20: =F19+7 -> 44509 | H20: Magnuson | J20: Tues Men's D Winter 21 | K20: 1 | L20: 14 | M20: =IF(C20>E20,"WIN",if(C20<E20,"DEFEAT","TIE")) -> WIN
A21: =A20+1 -> 20 | B21: {=INDEX(TeamsID!B:B,MATCH(K21,TeamsID!A:A,0))} -> Faceball | C21: 2 | D21: {=INDEX(TeamsID!B:B,MATCH(L21,TeamsID!A:A,0))} -> Brazukas | E21: 3 | F21: 44523 | H21: Magnuson | J21: Tues Men's D Winter 21 | K21: 8 | L21: 1 | M21: =IF(C21>E21,"WIN",if(C21<E21,"DEFEAT","TIE")) -> DEFEAT
A22: =A21+1 -> 21 | B22: {=INDEX(TeamsID!B:B,MATCH(K22,TeamsID!A:A,0))} -> Brazukas | C22: 3 | D22: {=INDEX(TeamsID!B:B,MATCH(L22,TeamsID!A:A,0))} -> Latin Heat | E22: 5 | F22: =F21+7 -> 44530 | H22: Magnuson | J22: Tues Men's D Winter 21 | K22: 1 | L22: 39 | M22: =IF(C22>E22,"WIN",if(C22<E22,"DEFEAT","TIE")) -> DEFEAT
A23: =A22+1 -> 22 | B23: {=INDEX(TeamsID!B:B,MATCH(K23,TeamsID!A:A,0))} -> Seattle Americans | C23: 5 | D23: {=INDEX(TeamsID!B:B,MATCH(L23,TeamsID!A:A,0))} -> Brazukas | E23: 2 | F23: =F22+7 -> 44537 | H23: Magnuson | J23: Tues Men's D Winter 21 | K23: 9 | L23: 1 | M23: =IF(C23>E23,"WIN",if(C23<E23,"DEFEAT","TIE")) -> WIN
A24: =A23+1 -> 23 | B24: {=INDEX(TeamsID!B:B,MATCH(K24,TeamsID!A:A,0))} -> FC Twente One | C24: 3 | D24: {=INDEX(TeamsID!B:B,MATCH(L24,TeamsID!A:A,0))} -> Brazukas | E24: 4 | F24: =F23+7 -> 44544 | H24: Magnuson | J24: Tues Men's D Winter 21 | K24: 10 | L24: 1 | M24: =IF(C24>E24,"WIN",if(C24<E24,"DEFEAT","TIE")) -> DEFEAT
A25: =A24+1 -> 24 | B25: {=INDEX(TeamsID!B:B,MATCH(K25,TeamsID!A:A,0))} -> No Tactics, Just Vibes | C25: 0 | D25: {=INDEX(TeamsID!B:B,MATCH(L25,TeamsID!A:A,0))} -> Brazukas | E25: 0 | F25: =F24+7 -> 44551 | H25: Magnuson | J25: Tues Men's D Winter 21 | K25: 11 | L25: 1 | M25: =IF(C25>E25,"WIN",if(C25<E25,"DEFEAT","TIE")) -> TIE
A26: =A25+1 -> 25 | B26: {=INDEX(TeamsID!B:B,MATCH(K26,TeamsID!A:A,0))} -> Magma | C26: 0 | D26: {=INDEX(TeamsID!B:B,MATCH(L26,TeamsID!A:A,0))} -> Brazukas | E26: 4 | F26: 44551 | H26: Magnuson | J26: Tues Men's D Winter 21 | K26: 12 | L26: 1 | M26: =IF(C26>E26,"WIN",if(C26<E26,"DEFEAT","TIE")) -> DEFEAT
A27: =A26+1 -> 26 | B27: {=INDEX(TeamsID!B:B,MATCH(K27,TeamsID!A:A,0))} -> Husar | C27: 5 | D27: {=INDEX(TeamsID!B:B,MATCH(L27,TeamsID!A:A,0))} -> Brazukas | E27: 3 | F27: 44565 | H27: Magnuson | J27: Tues Men's D Winter 21 | K27: 4 | L27: 1 | M27: =IF(C27>E27,"WIN",if(C27<E27,"DEFEAT","TIE")) -> WIN
A28: =A27+1 -> 27 | B28: {=INDEX(TeamsID!B:B,MATCH(K28,TeamsID!A:A,0))} -> Fuchester United | C28: 3 | D28: {=INDEX(TeamsID!B:B,MATCH(L28,TeamsID!A:A,0))} -> Brazukas | E28: 6 | F28: 44579 | H28: Magnuson | J28: Tues Men's D Winter II 22 | K28: 13 | L28: 1 | M28: =IF(C28>E28,"WIN",if(C28<E28,"DEFEAT","TIE")) -> DEFEAT
A29: =A28+1 -> 28 | B29: {=INDEX(TeamsID!B:B,MATCH(K29,TeamsID!A:A,0))} -> Brazukas | C29: 4 | D29: {=INDEX(TeamsID!B:B,MATCH(L29,TeamsID!A:A,0))} -> Faceball | E29: 4 | F29: 44958 | H29: Magnuson | J29: Tues Men's D Winter II 22 | K29: 1 | L29: 8 | M29: =IF(C29>E29,"WIN",if(C29<E29,"DEFEAT","TIE")) -> TIE
A30: =A29+1 -> 29 | B30: {=INDEX(TeamsID!B:B,MATCH(K30,TeamsID!A:A,0))} -> Brazukas | C30: 3 | D30: {=INDEX(TeamsID!B:B,MATCH(L30,TeamsID!A:A,0))} -> Husar | E30: 2 | F30: 44958 | H30: Magnuson | J30: Tues Men's D Winter II 22 | K30: 1 | L30: 4 | M30: =IF(C30>E30,"WIN",if(C30<E30,"DEFEAT","TIE")) -> WIN
A31: =A30+1 -> 30 | B31: {=INDEX(TeamsID!B:B,MATCH(K31,TeamsID!A:A,0))} -> FC Twente One | C31: 6 | D31: {=INDEX(TeamsID!B:B,MATCH(L31,TeamsID!A:A,0))} -> Brazukas | E31: 4 | F31: =F30+7 -> 44965 | H31: Magnuson | J31: Tues Men's D Winter II 22 | K31: 10 | L31: 1 | M31: =IF(C31>E31,"WIN",if(C31<E31,"DEFEAT","TIE")) -> WIN
A32: =A31+1 -> 31 | B32: {=INDEX(TeamsID!B:B,MATCH(K32,TeamsID!A:A,0))} -> Advil United | C32: 3 | D32: {=INDEX(TeamsID!B:B,MATCH(L32,TeamsID!A:A,0))} -> Brazukas | E32: 4 | F32: =F31+7 -> 44972 | H32: Magnuson | J32: Tues Men's D Winter II 22 | K32: 7 | L32: 1 | M32: =IF(C32>E32,"WIN",if(C32<E32,"DEFEAT","TIE")) -> DEFEAT
A33: =A32+1 -> 32 | B33: {=INDEX(TeamsID!B:B,MATCH(K33,TeamsID!A:A,0))} -> Brazukas | C33: 6 | D33: {=INDEX(TeamsID!B:B,MATCH(L33,TeamsID!A:A,0))} -> Crouch Potatoes | E33: 4 | F33: =F32+7 -> 44979 | H33: Magnuson | J33: Tues Men's D Winter II 22 | K33: 1 | L33: 14 | M33: =IF(C33>E33,"WIN",if(C33<E33,"DEFEAT","TIE")) -> WIN
A34: =A33+1 -> 33 | B34: {=INDEX(TeamsID!B:B,MATCH(K34,TeamsID!A:A,0))} -> Brazukas | C34: 2 | D34: {=INDEX(TeamsID!B:B,MATCH(L34,TeamsID!A:A,0))} -> Faceball | E34: 2 | F34: =F33+7 -> 44986 | H34: Magnuson | J34: Tues Men's D Winter II 22 | K34: 1 | L34: 8 | M34: =IF(C34>E34,"WIN",if(C34<E34,"DEFEAT","TIE")) -> TIE
A35: =A34+1 -> 34 | B35: {=INDEX(TeamsID!B:B,MATCH(K35,TeamsID!A:A,0))} -> Seattle Americans | C35: 10 | D35: {=INDEX(TeamsID!B:B,MATCH(L35,TeamsID!A:A,0))} -> Brazukas | E35: 7 | F35: =F34+7 -> 44993 | H35: Magnuson | J35: Tues Men's D Winter II 22 | K35: 9 | L35: 1 | M35: =IF(C35>E35,"WIN",if(C35<E35,"DEFEAT","TIE")) -> WIN
A36: =A35+1 -> 35 | B36: {=INDEX(TeamsID!B:B,MATCH(K36,TeamsID!A:A,0))} -> Brazukas | C36: 1 | D36: {=INDEX(TeamsID!B:B,MATCH(L36,TeamsID!A:A,0))} -> Blackfoot Ballers | E36: 6 | F36: =F35+7 -> 45000 | H36: Magnuson | J36: Tues Men's D Winter II 22 | K36: 1 | L36: 5 | M36: =IF(C36>E36,"WIN",if(C36<E36,"DEFEAT","TIE")) -> DEFEAT
A37: =A36+1 -> 36 | B37: {=INDEX(TeamsID!B:B,MATCH(K37,TeamsID!A:A,0))} -> Brazukas | C37: 13 | D37: {=INDEX(TeamsID!B:B,MATCH(L37,TeamsID!A:A,0))} -> Fuchester United | E37: 4 | F37: =F36+7 -> 45007 | H37: Magnuson | J37: Tues Men's D Winter II 22 | K37: 1 | L37: 13 | M37: =IF(C37>E37,"WIN",if(C37<E37,"DEFEAT","TIE")) -> WIN
A38: =A37+1 -> 37 | B38: {=INDEX(TeamsID!B:B,MATCH(K38,TeamsID!A:A,0))} -> Husar | C38: 2 | D38: {=INDEX(TeamsID!B:B,MATCH(L38,TeamsID!A:A,0))} -> Brazukas | E38: 4 | F38: =F37+7 -> 45014 | H38: Magnuson | J38: Tues Men's D Winter II 22 | K38: 4 | L38: 1 | M38: =IF(C38>E38,"WIN",if(C38<E38,"DEFEAT","TIE")) -> DEFEAT
A39: =A38+1 -> 38 | B39: {=INDEX(TeamsID!B:B,MATCH(K39,TeamsID!A:A,0))} -> FC Twente One | C39: 5 | D39: {=INDEX(TeamsID!B:B,MATCH(L39,TeamsID!A:A,0))} -> Brazukas | E39: 3 | F39: 44663 | H39: Magnuson | J39: Tues Men's D Winter II 22 | K39: 10 | L39: 1 | M39: =IF(C39>E39,"WIN",if(C39<E39,"DEFEAT","TIE")) -> WIN
A40: =A39+1 -> 39 | B40: {=INDEX(TeamsID!B:B,MATCH(K40,TeamsID!A:A,0))} -> Crouch Potatoes | C40: 2 | D40: {=INDEX(TeamsID!B:B,MATCH(L40,TeamsID!A:A,0))} -> Brazukas | E40: 1 | F40: 44670 | H40: Magnuson | J40: Tues Men's D Spring 22 | K40: 14 | L40: 1 | M40: =IF(C40>E40,"WIN",if(C40<E40,"DEFEAT","TIE")) -> WIN
...

Sheet PlayerID
A1: PlayerID | C1: Matches Played
A2: 1 | B2: Marcelo
A3: =A2+1 -> 2 | B3: Guilherme Souza
A4: =A3+1 -> 3 | B4: Joao Pinto
A5: =A4+1 -> 4 | B5: Rafael Franco
A6: =A5+1 -> 5 | B6: Joao Barros
A7: =A6+1 -> 6 | B7: Ranieri Filho
A8: =A7+1 -> 7 | B8: Sergio Filho
A9: =A8+1 -> 8 | B9: Cleiton Góes
A10: =A9+1 -> 9 | B10: Guilherme Kuster
A11: =A10+1 -> 10 | B11: Arthur Mendes | D11: 88 | E11: 110 | F11: 87
A12: =A11+1 -> 11 | B12: Pablo Rodrigues
A13: 12 | B13: Igor Kovacs
A14: 13 | B14: Caio Scofield
A15: 14 | B15: Marcelo Mazzafera
A16: 15 | B16: Gustavo Bitencourt
A17: 16 | B17: Tamir Guy
A18: 17 | B18: Luiz Felipe Mourao
A19: 18 | B19: Rafael Mattos
A20: 19 | B20: Emerson Bernardes
A21: 20 | B21: Flavio

Sheet TeamsID
A1: TeamID | B1: Home_Team | C1: Org | D1: Home Color | E1: Away Color | F1: Ex Name
A2: 1 | B2: Brazukas | C2: Magnuson | D2: White | E2: Yellow
A3: 2 | B3: RECEBA FC | C3: Redmond | D3: White | E3: Yellow
A4: 3 | B4: Immune to Defense | C4: Magnuson
A5: =A4+1 -> 4 | B5: Husar | C5: Magnuson
A6: =A5+1 -> 5 | B6: Blackfoot Ballers | C6: Magnuson
A7: =A6+1 -> 6 | B7: KOMPAS | C7: Magnuson
A8: =A7+1 -> 7 | B8: Advil United | C8: Magnuson
A9: =A8+1 -> 8 | B9: Faceball | C9: Magnuson
A10: =A9+1 -> 9 | B10: Seattle Americans | C10: Magnuson
A11: =A10+1 -> 10 | B11: FC Twente One | C11: Magnuson
A12: =A11+1 -> 11 | B12: No Tactics, Just Vibes | C12: Magnuson
A13: =A12+1 -> 12 | B13: Magma | C13: Magnuson
A14: =A13+1 -> 13 | B14: Fuchester United | C14: Magnuson
A15: =A14+1 -> 14 | B15: Crouch Potatoes | C15: Magnuson | F15: Show me da Mane
A16: =A15+1 -> 15 | B16: Edge Delta | C16: Magnuson
A17: =A16+1 -> 16 | B17: Wolves | C17: Magnuson
A18: =A17+1 -> 17 | B18: Un Real | C18: Magnuson
A19: =A18+1 -> 18 | B19: Kroos Control | C19: Magnuson
A20: =A19+1 -> 19 | B20: FC #!bash | C20: Magnuson
A21: =A20+1 -> 20 | B21: The Mighty Molars | C21: Magnuson
A22: =A21+1 -> 21 | B22: Supermokh FC | C22: Magnuson
A23: =A22+1 -> 22 | B23: Advil | C23: Magnuson
A24: =A23+1 -> 23 | B24: Tuesday Gold | C24: Magnuson
A25: =A24+1 -> 24 | B25: Mid Field Crisis | C25: Magnuson
A26: =A25+1 -> 25 | B26: Crouch Potatoes | C26: Magnuson
A27: =A26+1 -> 26 | B27: Axolotls | C27: Magnuson
... A47: =A46+1 -> 46 | B47: Dribblers FC | C47: Redmond
A48: =A47+1 -> 47 | B48: Team Cookie
A49: =A48+1 -> 48 | B49: Schedule Chickens
A50: =A49+1 -> 49 | B50: Real Mandrink
A51: =A50+1 -> 50 | B51: Pipe Dream
A52: =A51+1 -> 51 | B52: Dirty Dozen
A53: =A52+1 -> 52 | B53: Casa Real AC
